<?xml version="1.0" encoding="utf-8"?>

<robot
  name="human_robot">
<!-- 
<link name="world"/>
  <joint name="base" type="fixed">
    <parent link="world"/>
    <child link="body_link"/>
  </joint> -->


<link name="base_link"/>
<joint name="base" type="fixed">
    <parent link="base_link"/>
    <child link="body_link"/>
  </joint>

  <link
    name="body_link">
    <inertial>
      <origin
        xyz="0.00031235 -0.0075844 -0.018215"
        rpy="0 0 0" />
      <mass
        value="0.36015" />
      <inertia
        ixx="0.0002423"
        ixy="0.0"
        ixz="0.0"
        iyy="0.0002723"
        iyz="0.0"
        izz="0.00025037" />
    </inertial>
    <visual>
      <origin
        xyz="0 0 0"
        rpy="0 0 0" />
      <geometry>
        <mesh
          filename="package://humanrobo/src/meshes/body_link.STL" />
          <!-- <box size="0.01 0.01 0.01"/> -->
      </geometry>
      <material
        name="">
        <color
          rgba="0.75294 0.75294 0.75294 1" />
      </material>
    </visual>
    <collision>
      <origin
        xyz="0 0 0"
        rpy="0 0 0" />
      <geometry>
        <!-- <mesh
          filename="package://humanrobo/src/meshes/body_link.STL" /> -->
          <box size="0.01 0.01 0.01"/>
      </geometry>
    </collision>
  </link>
   <link
    name="imu_link">
    <inertial>
      <origin
        xyz="0.0 0.0 0.0"
        rpy="0 0 0" />
      <mass
        value="0.0000001" />
      <inertia
        ixx="1.0E-13"
        ixy="0.0"
        ixz="0.0"
        iyy="1.0E-13"
        iyz="0.0"
        izz="1.0E-13" />
    </inertial>
    <visual>
      <origin
        xyz="0 0 0.0"
        rpy="0 0 0" />
      <geometry>
        <cylinder length="0.02" radius="0.02"/>
      </geometry>
      <material
        name="">
        <color
          rgba="0.752941176470588 0.752941176470588 0.752941176470588 1" />
      </material>
    </visual>
    <collision>
      <origin
        xyz="0 0 0.0"
        rpy="0 0 0" />
      <geometry>
        <cylinder length="0.01" radius="0.01"/>
      </geometry>
    </collision>
  </link>
 <joint name="imu_joint" type="fixed">
        <parent link="body_link" />
        <child link="imu_link" />
        <origin xyz="0 0 0.0" />
 </joint>
 <gazebo reference="imu_link">
      <sensor name="imu_sensor" type="imu">
      <plugin filename="libgazebo_ros_imu_sensor.so" name="imu_plugin">
          <ros>
            <namespace>/humanrobo/imu</namespace>
            <remapping>~/out:=imu</remapping>
          </ros>
          <initial_orientation_as_reference>false</initial_orientation_as_reference>
          <topicName>/humanrobo/imu</topicName>
          <frameName>imu_link</frameName>
          <updateRateHZ>50</updateRateHZ>
        </plugin>
        <always_on>true</always_on>
        <update_rate>50</update_rate>
        <visualize>true</visualize>
        
        <imu>
          <angular_velocity>
            <x>
              <noise type="gaussian">
                <mean>0.0</mean>
                <stddev>2e-4</stddev>
                <bias_mean>0.0000075</bias_mean>
                <bias_stddev>0.0000008</bias_stddev>
              </noise>
            </x>
            <y>
              <noise type="gaussian">
                <mean>0.0</mean>
                <stddev>2e-4</stddev>
                <bias_mean>0.0000075</bias_mean>
                <bias_stddev>0.0000008</bias_stddev>
              </noise>
            </y>
            <z>
              <noise type="gaussian">
                <mean>0.0</mean>
                <stddev>2e-4</stddev>
                <bias_mean>0.0000075</bias_mean>
                <bias_stddev>0.0000008</bias_stddev>
              </noise>
            </z>
          </angular_velocity>
          <linear_acceleration>
            <x>
              <noise type="gaussian">
                <mean>0.0</mean>
                <stddev>1.7e-2</stddev>
                <bias_mean>0.1</bias_mean>
                <bias_stddev>0.001</bias_stddev>
              </noise>
            </x>
            <y>
              <noise type="gaussian">
                <mean>0.0</mean>
                <stddev>1.7e-2</stddev>
                <bias_mean>0.1</bias_mean>
                <bias_stddev>0.001</bias_stddev>
              </noise>
            </y>
            <z>
              <noise type="gaussian">
                <mean>0.0</mean>
                <stddev>1.7e-2</stddev>
                <bias_mean>0.1</bias_mean>
                <bias_stddev>0.001</bias_stddev>
              </noise>
            </z>
          </linear_acceleration>
        </imu>
      </sensor>
    </gazebo>
  <link
    name="neck_Link">
    <inertial>
      <origin
        xyz="3.3775E-06 0.016907 -0.00057139"
        rpy="0 0 0" />
      <mass
        value="0.023818" />
      <inertia
        ixx="4.382E-06"
        ixy="0"
        ixz="0"
        iyy="3.561E-06"
        iyz="0"
        izz="2.39E-06" />
    </inertial>
    <visual>
      <origin
        xyz="0 0 0"
        rpy="0 0 0" />
      <geometry>
        <mesh
          filename="package://humanrobo/src/meshes/neck_Link.STL" />
          <!-- <box size="0.01 0.01 0.01"/> -->
      </geometry>
      <material
        name="">
        <color
          rgba="0.75294 0.75294 0.75294 1" />
      </material>
    </visual>
    <collision>
      <origin
        xyz="0 0 0"
        rpy="0 0 0" />
      <geometry>
        <!-- <mesh
          filename="package://humanrobo/src/meshes/neck_Link.STL" /> -->
          <box size="0.01 0.01 0.01"/>
      </geometry>
    </collision>
  </link>
  <joint
    name="neck_yaw"
    type="fixed">


    <origin
      xyz="0 -0.0056956 0.0166"
      rpy="1.5708 0 0" />
    <parent
      link="body_link" />
    <child
      link="neck_Link" />
    <axis
      xyz="0 1 0" />
  </joint>
  <link
    name="face_Link">
    <inertial>
      <origin
        xyz="2.1608E-09 -0.0068654 0.0004"
        rpy="0 0 0" />
      <mass
        value="0.0043952" />
      <inertia
        ixx="1.0402E-06"
        ixy="0"
        ixz="0"
        iyy="1.8626E-06"
        iyz="0"
        izz="1.0429E-06" />
    </inertial>
    <visual>
      <origin
        xyz="0 0 0"
        rpy="0 0 0" />
      <geometry>
        <mesh
          filename="package://humanrobo/src/meshes/face_Link.STL" />
          <!-- <box size="0.01 0.01 0.01"/> -->
      </geometry>
      <material
        name="">
        <color
          rgba="0.25098 0.25098 0.25098 1" />
      </material>
    </visual>
    <collision>
      <origin
        xyz="0 0 0"
        rpy="0 0 0" />
      <geometry>
        <!-- <mesh
          filename="package://humanrobo/src/meshes/face_Link.STL" /> -->
          <box size="0.01 0.01 0.01"/>
      </geometry>
    </collision>
  </link>
  <joint
    name="neck_roll"
    type="fixed">


    <origin
      xyz="0 0.023272 0"
      rpy="-3.1416 0 0" />
    <parent
      link="neck_Link" />
    <child
      link="face_Link" />
    <axis
      xyz="0 0 1" />
  </joint>
  <link
    name="head_Link">
    <inertial>
      <origin
        xyz="-0.0047445 3.9018E-06 0.00026335"
        rpy="0 0 0" />
      <mass
        value="0.020617" />
      <inertia
        ixx="3.05E-06"
        ixy="0"
        ixz="0"
        iyy="3.64E-06"
        iyz="0"
        izz="1.61E-06" />
    </inertial>
    <visual>
      <origin
        xyz="0 0 0"
        rpy="0 0 0" />
      <geometry>
        <mesh
          filename="package://humanrobo/src/meshes/head_Link.STL" />
          <!-- <box size="0.01 0.01 0.01"/> -->
      </geometry>
      <material
        name="">
        <color
          rgba="0.75294 0.75294 0.75294 1" />
      </material>
    </visual>
    <collision>
      <origin
        xyz="0 0 0"
        rpy="0 0 0" />
      <geometry>
        <!-- <mesh
          filename="package://humanrobo/src/meshes/head_Link.STL" /> -->
          <box size="0.01 0.01 0.01"/>
      </geometry>
    </collision>
  </link>
  <joint
    name="neck_pitch"
    type="fixed">


    <origin
      xyz="0 -0.01392 0.0004"
      rpy="-1.5708 0 1.5708" />
    <parent
      link="face_Link" />
    <child
      link="head_Link" />
    <axis
      xyz="0 0 1" />
  </joint>
  <link
    name="L_shoulder_Link">
    <inertial>
      <origin
        xyz="0.024716 0.00017384 4.406E-05"
        rpy="0 0 0" />
      <mass
        value="0.024989" />
      <inertia
        ixx="3.77E-06"
        ixy="0"
        ixz="0"
        iyy="5.4E-06"
        iyz="0"
        izz="3.37E-06" />
    </inertial>
    <visual>
      <origin
        xyz="0 0 0"
        rpy="0 0 0" />
      <geometry>
        <mesh
          filename="package://humanrobo/src/meshes/L_shoulder_Link.STL" />
          <!-- <box size="0.01 0.01 0.01"/> -->
      </geometry>
      <material
        name="">
        <color
          rgba="0.75294 0.75294 0.75294 1" />
      </material>
    </visual>
    <collision>
      <origin
        xyz="0 0 0"
        rpy="0 0 0" />
      <geometry>
        <!-- <mesh
          filename="package://humanrobo/src/meshes/L_shoulder_Link.STL" /> -->
          <box size="0.01 0.01 0.01"/>
      </geometry>
    </collision>
  </link>
  <joint
    name="L_shoulder_BF"
    type="fixed">


    <origin
      xyz="0.044847 0 0"
      rpy="1.6211 -0.00060792 0.02417" />
    <parent
      link="body_link" />
    <child
      link="L_shoulder_Link" />
    <axis
      xyz="0.99971 0.00060792 0.024168" />
  </joint>
  <link
    name="L_arm_Link">
    <inertial>
      <origin
        xyz="0.00014899 -0.025512 0.00056858"
        rpy="0 0 0" />
      <mass
        value="0.028234" />
      <inertia
        ixx="4.6E-06"
        ixy="0"
        ixz="0"
        iyy="3.76E-06"
        iyz="0"
        izz="4.71E-06" />
    </inertial>
    <visual>
      <origin
        xyz="0 0 0"
        rpy="0 0 0" />
      <geometry>
        <mesh
          filename="package://humanrobo/src/meshes/L_arm_Link.STL" />
          <!-- <box size="0.01 0.01 0.01"/> -->
      </geometry>
      <material
        name="">
        <color
          rgba="0.75294 0.75294 0.75294 1" />
      </material>
    </visual>
    <collision>
      <origin
        xyz="0 0 0"
        rpy="0 0 0" />
      <geometry>
        <!-- <mesh
          filename="package://humanrobo/src/meshes/L_arm_Link.STL" /> -->
          <box size="0.01 0.01 0.01"/>
      </geometry>
    </collision>
  </link>
  <joint
    name="L_shoulder_IO"
    type="fixed">


    <origin
      xyz="0.032545 1.979E-05 0.00078676"
      rpy="0 0 0" />
    <parent
      link="L_shoulder_Link" />
    <child
      link="L_arm_Link" />
    <axis
      xyz="0.024168 -0.050269 -0.99844" />
  </joint>
  <link
    name="L_elbow_Link">
    <inertial>
      <origin
        xyz="0.0064111 -0.0051776 0.00010597"
        rpy="0 0 0" />
      <mass
        value="0.003398" />
      <inertia
        ixx="2.4076E-07"
        ixy="0"
        ixz="0"
        iyy="8.0772E-07"
        iyz="0"
        izz="7.9803E-07" />
    </inertial>
    <visual>
      <origin
        xyz="0 0 0"
        rpy="0 0 0" />
      <geometry>
        <mesh
          filename="package://humanrobo/src/meshes/L_elbow_Link.STL" />
          <!-- <box size="0.01 0.01 0.01"/> -->
      </geometry>
      <material
        name="">
        <color
          rgba="0.89804 0.91765 0.92941 1" />
      </material>
    </visual>
    <collision>
      <origin
        xyz="0 0 0"
        rpy="0 0 0" />
      <geometry>
        <!-- <mesh
          filename="package://humanrobo/src/meshes/L_elbow_Link.STL" /> -->
          <box size="0.01 0.01 0.01"/>
      </geometry>
    </collision>
  </link>
  <joint
    name="L_elbow_SP"
    type="fixed">


    <origin
      xyz="0.0060743 -0.041588 0.0013098"
      rpy="-3.0913 0.02417 -3.141" />
    <parent
      link="L_arm_Link" />
    <child
      link="L_elbow_Link" />
    <axis
      xyz="0 1 0" />
  </joint>
  <link
    name="L_armD_Link">
    <inertial>
      <origin
        xyz="-0.0064821 -0.029607 0.00012813"
        rpy="0 0 0" />
      <mass
        value="0.052503" />
      <inertia
        ixx="3.232E-05"
        ixy="0"
        ixz="0"
        iyy="8.37E-06"
        iyz="-00"
        izz="3.267E-05" />
    </inertial>
    <visual>
      <origin
        xyz="0 0 0"
        rpy="0 0 0" />
      <geometry>
        <mesh
          filename="package://humanrobo/src/meshes/L_armD_Link.STL" />
          <!-- <box size="0.01 0.01 0.01"/> -->
      </geometry>
      <material
        name="">
        <color
          rgba="0.75294 0.75294 0.75294 1" />
      </material>
    </visual>
    <collision>
      <origin
        xyz="0 0 0"
        rpy="0 0 0" />
      <geometry>
        <!-- <mesh
          filename="package://humanrobo/src/meshes/L_armD_Link.STL" /> -->
          <box size="0.01 0.01 0.01"/>
      </geometry>
    </collision>
  </link>
  <joint
    name="L_elbow_BD"
    type="fixed">


    <origin
      xyz="0 -0.018128 0.00010004"
      rpy="-3.1416 -0.02417 -3.141" />
    <parent
      link="L_elbow_Link" />
    <child
      link="L_armD_Link" />
    <axis
      xyz="0.99971 0.00060792 0.024168" />
  </joint>
  <link
    name="L_hand_Link">
    <inertial>
      <origin
        xyz="-0.0024325 -0.020572 0.00035"
        rpy="0 0 0" />
      <mass
        value="0.001859" />
      <inertia
        ixx="6.55E-07"
        ixy="0"
        ixz="0"
        iyy="5.1338E-07"
        iyz="0"
        izz="2.5197E-07" />
    </inertial>
    <visual>
      <origin
        xyz="0 0 0"
        rpy="0 0 0" />
      <geometry>
        <mesh
          filename="package://humanrobo/src/meshes/L_hand_Link.STL" />
          <!-- <box size="0.01 0.01 0.01"/> -->
      </geometry>
      <material
        name="">
        <color
          rgba="0.25098 0.25098 0.25098 1" />
      </material>
    </visual>
    <collision>
      <origin
        xyz="0 0 0"
        rpy="0 0 0" />
      <geometry>
        <!-- <mesh
          filename="package://humanrobo/src/meshes/L_hand_Link.STL" /> -->
          <box size="0.01 0.01 0.01"/>
      </geometry>
    </collision>
  </link>
  <joint
    name="L_hand"
    type="fixed">


    <origin
      xyz="-0.0048671 -0.05515 -0.00011766"
      rpy="-1.4696E-05 -0.02417 0.0006081" />
    <parent
      link="L_armD_Link" />
    <child
      link="L_hand_Link" />
    <axis
      xyz="0 0 1" />
  </joint>
  <link
    name="R_shoulder_Link">
    <inertial>
      <origin
        xyz="-0.023927 0.00019287 -0.00055003"
        rpy="0 0 0" />
      <mass
        value="0.024989" />
      <inertia
        ixx="3.77E-06"
        ixy="0"
        ixz="0"
        iyy="5.41E-06"
        iyz="0"
        izz="3.37E-06" />
    </inertial>
    <visual>
      <origin
        xyz="0 0 0"
        rpy="0 0 0" />
      <geometry>
        <mesh
          filename="package://humanrobo/src/meshes/R_shoulder_Link.STL" />
          <!-- <box size="0.01 0.01 0.01"/> -->
      </geometry>
      <material
        name="">
        <color
          rgba="0.75294 0.75294 0.75294 1" />
      </material>
    </visual>
    <collision>
      <origin
        xyz="0 0 0"
        rpy="0 0 0" />
      <geometry>
        <!-- <mesh
          filename="package://humanrobo/src/meshes/R_shoulder_Link.STL" /> -->
          <box size="0.01 0.01 0.01"/>
      </geometry>
    </collision>
  </link>
  <joint
    name="R_shoulder_BF"
    type="fixed">


    <origin
      xyz="-0.04523 0 0"
      rpy="1.5708 0 0" />
    <parent
      link="body_link" />
    <child
      link="R_shoulder_Link" />
    <axis
      xyz="1 0 0" />
  </joint>
  <link
    name="R_arm_Link">
    <inertial>
      <origin
        xyz="-8.455E-05 -0.02551 -0.00029441"
        rpy="0 0 0" />
      <mass
        value="0.028234" />
      <inertia
        ixx="4.6004E-06"
        ixy="0"
        ixz="0"
        iyy="3.75E-06"
        iyz="0"
        izz="4.71E-06" />
    </inertial>
    <visual>
      <origin
        xyz="0 0 0"
        rpy="0 0 0" />
      <geometry>
        <mesh
          filename="package://humanrobo/src/meshes/R_arm_Link.STL" />
          <!-- <box size="0.01 0.01 0.01"/> -->
      </geometry>
      <material
        name="">
        <color
          rgba="0.75294 0.75294 0.75294 1" />
      </material>
    </visual>
    <collision>
      <origin
        xyz="0 0 0"
        rpy="0 0 0" />
      <geometry>
        <!-- <mesh
          filename="package://humanrobo/src/meshes/R_arm_Link.STL" /> -->
          <box size="0.01 0.01 0.01"/>
      </geometry>
    </collision>
  </link>
  <joint
    name="R_shoulder_IO"
    type="fixed">


    <origin
      xyz="-0.031773 0 0"
      rpy="0 0 0" />
    <parent
      link="R_shoulder_Link" />
    <child
      link="R_arm_Link" />
    <axis
      xyz="0 0 1" />
  </joint>
  <link
    name="R_elbow_Link">
    <inertial>
      <origin
        xyz="0.0064111 -0.0051776 0.00010597"
        rpy="0 0 0" />
      <mass
        value="0.003398" />
      <inertia
        ixx="2.4076E-07"
        ixy="0"
        ixz="0"
        iyy="8.0772E-07"
        iyz="0"
        izz="7.9803E-07" />
    </inertial>
    <visual>
      <origin
        xyz="0 0 0"
        rpy="0 0 0" />
      <geometry>
        <mesh
          filename="package://humanrobo/src/meshes/R_elbow_Link.STL" />
          <!-- <box size="0.01 0.01 0.01"/> -->
      </geometry>
      <material
        name="">
        <color
          rgba="0.89804 0.91765 0.92941 1" />
      </material>
    </visual>
    <collision>
      <origin
        xyz="0 0 0"
        rpy="0 0 0" />
      <geometry>
        <!-- <mesh
          filename="package://humanrobo/src/meshes/R_elbow_Link.STL" /> -->
          <box size="0.01 0.01 0.01"/>
      </geometry>
    </collision>
  </link>
  <joint
    name="R_elbow_SP"
    type="fixed">


    <origin
      xyz="-0.006 -0.0416 -0.00030004"
      rpy="0 0 0" />
    <parent
      link="R_arm_Link" />
    <child
      link="R_elbow_Link" />
    <axis
      xyz="0 1 0" />
  </joint>
  <link
    name="R_armD_Link">
    <inertial>
      <origin
        xyz="0.0067823 -0.029623 0.00044333"
        rpy="0 0 0" />
      <mass
        value="0.052503" />
      <inertia
        ixx="3.237E-05"
        ixy="0"
        ixz="0"
        iyy="8.41E-06"
        iyz="0"
        izz="3.274E-05" />
    </inertial>
    <visual>
      <origin
        xyz="0 0 0"
        rpy="0 0 0" />
      <geometry>
        <mesh
          filename="package://humanrobo/src/meshes/R_armD_Link.STL" />
          <!-- <box size="0.01 0.01 0.01"/> -->
      </geometry>
      <material
        name="">
        <color
          rgba="0.75294 0.75294 0.75294 1" />
      </material>
    </visual>
    <collision>
      <origin
        xyz="0 0 0"
        rpy="0 0 0" />
      <geometry>
        <!-- <mesh
          filename="package://humanrobo/src/meshes/R_armD_Link.STL" /> -->
          <box size="0.01 0.01 0.01"/>
      </geometry>
    </collision>
  </link>
  <joint
    name="R_elbow_BD"
    type="fixed">


    <origin
      xyz="0 -0.018128 0.00010004"
      rpy="0 0 0" />
    <parent
      link="R_elbow_Link" />
    <child
      link="R_armD_Link" />
    <axis
      xyz="1 0 0" />
  </joint>
  <link
    name="R_hand_Link">
    <inertial>
      <origin
        xyz="-0.0024325 -0.020572 -0.00093518"
        rpy="0 0 0" />
      <mass
        value="0.001859" />
      <inertia
        ixx="6.55E-07"
        ixy="0"
        ixz="0"
        iyy="5.1338E-07"
        iyz="0"
        izz="2.5197E-07" />
    </inertial>
    <visual>
      <origin
        xyz="0 0 0"
        rpy="0 0 0" />
      <geometry>
        <mesh
          filename="package://humanrobo/src/meshes/R_hand_Link.STL" />
          <!-- <box size="0.01 0.01 0.01"/> -->
      </geometry>
      <material
        name="">
        <color
          rgba="0.25098 0.25098 0.25098 1" />
      </material>
    </visual>
    <collision>
      <origin
        xyz="0 0 0"
        rpy="0 0 0" />
      <geometry>
        <!-- <mesh
          filename="package://humanrobo/src/meshes/R_hand_Link.STL" /> -->
          <box size="0.01 0.01 0.01"/>
      </geometry>
    </collision>
  </link>
  <joint
    name="R_hand"
    type="fixed">
    <origin
      xyz="0.0057924 -0.055194 0"
      rpy="-3.1416 0 -3.1416" />
    <parent
      link="R_armD_Link" />
    <child
      link="R_hand_Link" />
    <axis
      xyz="0 0 1" />
  </joint>
  <link
    name="bodyD_Link">
    <inertial>
      <origin
        xyz="-0.0015723 -0.014811 -0.00028399"
        rpy="0 0 0" />
      <mass
        value="0.0043579" />
      <inertia
        ixx="1.357E-06"
        ixy="0"
        ixz="0"
        iyy="1.3964E-06"
        iyz="0"
        izz="3.7932E-07" />
    </inertial>
    <visual>
      <origin
        xyz="0 0 0"
        rpy="0 0 0" />
      <geometry>
        <mesh
          filename="package://humanrobo/src/meshes/bodyD_Link.STL" />
          <!-- <box size="0.01 0.01 0.01"/> -->
      </geometry>
      <material
        name="">
        <color
          rgba="0.89804 0.91765 0.92941 1" />
      </material>
    </visual>
    <collision>
      <origin
        xyz="0 0 0"
        rpy="0 0 0" />
      <geometry>
        <!-- <mesh
          filename="package://humanrobo/src/meshes/bodyD_Link.STL" /> -->
          <box size="0.01 0.01 0.01"/>
      </geometry>
    </collision>
  </link>
  <joint
    name="waist_bow"
    type="fixed">

<!--  -->
    <origin
      xyz="0 0 -0.052002"
      rpy="1.5708 0 -1.5708" />
      <!-- <origin
      xyz="0 9.6389E-05 -0.052002"
      rpy="1.5708 0 -1.5708" /> -->
    <parent
      link="body_link" />
    <child
      link="bodyD_Link" />
    <axis
      xyz="0 0 1" />
  </joint>
  <link
    name="waist_Link">
    <inertial>
      <origin
        xyz="3.2702E-05 -0.014662 -0.006628"
        rpy="0 0 0" />
      <mass
        value="0.10912" />
      <inertia
        ixx="1.84E-05"
        ixy="0.0"
        ixz="0.0"
        iyy="0.00011"
        iyz="0.0"
        izz="0.00011273" />
    </inertial>
    <visual>
      <origin
        xyz="0 0 0"
        rpy="0 0 0" />
      <geometry>
        <mesh
          filename="package://humanrobo/src/meshes/waist_Link.STL" />
          <!-- <box size="0.01 0.01 0.01"/> -->
      </geometry>
      <material
        name="">
        <color
          rgba="0.75294 0.75294 0.75294 1" />
      </material>
    </visual>
    <collision>
      <origin
        xyz="0 0 0"
        rpy="0 0 0" />
      <geometry>
        <!-- <mesh
          filename="package://humanrobo/src/meshes/waist_Link.STL" /> -->
          <box size="0.01 0.01 0.01"/>
      </geometry>
    </collision>
  </link>
  <joint
    name="waist_SP"
    type="fixed">
    <origin
      xyz="-0.0022 -0.02 -0.00028397"
      rpy="0 1.5708 0" />
    <parent
      link="bodyD_Link" />
    <child
      link="waist_Link" />
    <axis
      xyz="0 1 0" />
  </joint>
  <link
    name="L_hip_Link">
    <inertial>
      <origin
        xyz="-0.019345290107797 -0.0121029945148015 0.00909334937738589"
        rpy="0 0 0" />
      <mass
        value="0.0276397239506233" />
      <inertia
        ixx="2.6E-06"
        ixy="0"
        ixz="0"
        iyy="3.96E-06"
        iyz="0"
        izz="5.65E-06" />
    </inertial>
    <visual>
      <origin
        xyz="0 0 0"
        rpy="0 0 0" />
      <geometry>
        <mesh
          filename="package://humanrobo/src/meshes/L_hip_Link.STL" />
          <!-- <box size="0.01 0.01 0.01"/> -->
      </geometry>
      <material
        name="">
        <color
          rgba="0.752941176470588 0.752941176470588 0.752941176470588 1" />
      </material>
    </visual>
    <collision>
      <origin
        xyz="0 0 0"
        rpy="0 0 0" />
      <geometry>
        <!-- <mesh
          filename="package://humanrobo/src/meshes/L_hip_Link.STL" /> -->
          <box size="0.01 0.01 0.01"/>
      </geometry>
    </collision>
  </link>
  <joint
    name="L_hip_IO"
    type="continuous">
     <dynamics damping="0.002"/>


    <origin
      xyz="0.044501 -0.019602 0.004238"
      rpy="0 0 0" />
    <parent
      link="waist_Link" />
    <child
      link="L_hip_Link" />
    <axis
      xyz="0 0 1" />
  </joint>
  <link
    name="L_thign_Link">
    <inertial>
      <origin
        xyz="-0.0036508 -0.008552 -0.010987"
        rpy="0 0 0" />
      <mass
        value="0.006204" />
      <inertia
        ixx="2.3895E-06"
        ixy="0"
        ixz="0"
        iyy="2.1933E-06"
        iyz="0"
        izz="9.0729E-07" />
    </inertial>
    <visual>
      <origin
        xyz="0 0 0"
        rpy="0 0 0" />
      <geometry>
        <mesh
          filename="package://humanrobo/src/meshes/L_thign_Link.STL" />
          <!-- <box size="0.01 0.01 0.01"/> -->
      </geometry>
      <material
        name="">
        <color
          rgba="0.89804 0.91765 0.92941 1" />
      </material>
    </visual>
    <collision>
      <origin
        xyz="0 0 0"
        rpy="0 0 0" />
      <geometry>
        <!-- <mesh
          filename="package://humanrobo/src/meshes/L_thign_Link.STL" /> -->
          <box size="0.01 0.01 0.01"/>
      </geometry>
    </collision>
  </link>
  <joint
    name="L_thign_SP"
    type="continuous">
     <dynamics damping="0.002"/>


    <origin
      xyz="-0.028692 -0.0263 0.009"
      rpy="1.5708 -1.5708 -1.5708" />
    <parent
      link="L_hip_Link" />
    <child
      link="L_thign_Link" />
    <axis
      xyz="0 1 0" />
  </joint>
  <link
    name="L_thignD_Link">
    <inertial>
      <origin
        xyz="0.009327 -0.026501 -2.0196E-08"
        rpy="0 0 0" />
      <mass
        value="0.075003" />
      <inertia
        ixx="3.977E-05"
        ixy="0"
        ixz="0"
        iyy="1.39E-05"
        iyz="0"
        izz="4.122E-05" />
    </inertial>
    <visual>
      <origin
        xyz="0 0 0"
        rpy="0 0 0" />
      <geometry>
        <mesh
          filename="package://humanrobo/src/meshes/L_thignD_Link.STL" />
          <!-- <box size="0.01 0.01 0.01"/> -->
      </geometry>
      <material
        name="">
        <color
          rgba="0.75294 0.75294 0.75294 1" />
      </material>
    </visual>
    <collision>
      <origin
        xyz="0 0 0"
        rpy="0 0 0" />
      <geometry>
        <!-- <mesh
          filename="package://humanrobo/src/meshes/L_thignD_Link.STL" /> -->
          <box size="0.01 0.01 0.01"/>
      </geometry>
    </collision>
  </link>
  <joint
    name="L_thign_BF"
    type="continuous">
     <dynamics damping="0.002"/>


    <origin
      xyz="-0.0078324 -0.022002 0"
      rpy="0 1.5708 0" />
    <parent
      link="L_thign_Link" />
    <child
      link="L_thignD_Link" />
    <axis
      xyz="1 0 0" />
  </joint>
  <link
    name="L_shank_Link">
    <inertial>
      <origin
        xyz="0.0097137 -0.034273 0.0005591"
        rpy="0 0 0" />
      <mass
        value="0.057967" />
      <inertia
        ixx="2.36E-05"
        ixy="0"
        ixz="0"
        iyy="1.507E-05"
        iyz="0"
        izz="2.877E-05" />
    </inertial>
    <visual>
      <origin
        xyz="0 0 0"
        rpy="0 0 0" />
      <geometry>
        <mesh
          filename="package://humanrobo/src/meshes/L_shank_Link.STL" />
          <!-- <box size="0.01 0.01 0.01"/> -->
      </geometry>
      <material
        name="">
        <color
          rgba="0.75294 0.75294 0.75294 1" />
      </material>
    </visual>
    <collision>
      <origin
        xyz="0 0 0"
        rpy="0 0 0" />
      <geometry>
        <!-- <mesh
          filename="package://humanrobo/src/meshes/L_shank_Link.STL" /> -->
          <box size="0.01 0.01 0.01"/>
      </geometry>
    </collision>
  </link>
  <joint
    name="L_knee"
    type="continuous">
     <dynamics damping="0.002"/>


    <origin
      xyz="0 -0.053002 0"
      rpy="0 0 0" />
    <parent
      link="L_thignD_Link" />
    <child
      link="L_shank_Link" />
    <axis
      xyz="1 0 0" />
  </joint>
  <link
    name="L_ankle_Link">
    <inertial>
      <origin
        xyz="-0.00013247 -0.0089377 0.0099976"
        rpy="0 0 0" />
      <mass
        value="0.0265" />
      <inertia
        ixx="1.0413E-05"
        ixy="0"
        ixz="-00"
        iyy="1.5837E-05"
        iyz="0"
        izz="1.1392E-05" />
    </inertial>
    <visual>
      <origin
        xyz="0 0 0"
        rpy="0 0 0" />
      <geometry>
        <mesh
          filename="package://humanrobo/src/meshes/L_ankle_Link.STL" />
          <!-- <box size="0.01 0.01 0.01"/> -->
      </geometry>
      <material
        name="">
        <color
          rgba="0.89804 0.91765 0.92941 1" />
      </material>
    </visual>
    <collision>
      <origin
        xyz="0 0 0"
        rpy="0 0 0" />
      <geometry>
        <!-- <mesh
          filename="package://humanrobo/src/meshes/L_ankle_Link.STL" /> -->
          <box size="0.01 0.01 0.01"/>
      </geometry>
    </collision>
  </link>
  <joint
    name="L_ankle_BF"
    type="continuous">
     <dynamics damping="0.002"/>


    <origin
      xyz="0 -0.05329 0"
      rpy="1.5708 1.5708 1.5708" />
    <parent
      link="L_shank_Link" />
    <child
      link="L_ankle_Link" />
    <axis
      xyz="0 0 1" />
  </joint>
  <link
    name="L_foot_Link">
    <inertial>
      <origin
        xyz="0.0075693 -0.0053088 0.005564"
        rpy="0 0 0" />
      <mass
        value="0.055122" />
      <inertia
        ixx="1.96E-05"
        ixy="0"
        ixz="0"
        iyy="2.29E-05"
        iyz="-0"
        izz="1.331E-05" />
    </inertial>
    <visual>
      <origin
        xyz="0.0085 -0.0112 0.005"
        rpy="0 0 0" />
      <geometry>
        <!-- <mesh
          filename="package://humanrobo/src/meshes/L_foot_Link.STL" /> -->
          <box size="0.041 0.011 0.055"/>
      </geometry>
      <material
        name="">
        <color
          rgba="0.75294 0.75294 0.75294 1" />
      </material>
    </visual>
    <collision>
      <origin
        xyz="0.0085 -0.0112 0.005"
        rpy="0 0 0" />
      <geometry>
        <!-- <mesh
          filename="package://humanrobo/src/meshes/L_foot_Link.STL" /> -->
        <box size="0.041 0.011 0.055"/>
      </geometry>
    </collision>
  </link>
  <joint
    name="L_foot"
    type="continuous">
     <dynamics damping="0.002"/>


    <origin
      xyz="0 -0.027997 0.002143"
      rpy="-1.5708 -1.5708 1.5708" />
    <parent
      link="L_ankle_Link" />
    <child
      link="L_foot_Link" />
    <axis
      xyz="0 0 1" />
  </joint>
  <link
    name="R_hip_Link">
    <inertial>
      <origin
        xyz="0.019345 -0.012103 0.0089067"
        rpy="0 0 0" />
      <mass
        value="0.02764" />
      <inertia
        ixx="2.6E-06"
        ixy="0"
        ixz="0"
        iyy="3.96E-06"
        iyz="0"
        izz="5.65E-06" />
    </inertial>
    <visual>
      <origin
        xyz="0 0 0"
        rpy="0 0 0" />
      <geometry>
        <mesh
          filename="package://humanrobo/src/meshes/R_hip_Link.STL" />
          <!-- <box size="0.01 0.01 0.01"/> -->
      </geometry>
      <material
        name="">
        <color
          rgba="0.75294 0.75294 0.75294 1" />
      </material>
    </visual>
    <collision>
      <origin
        xyz="0 0 0"
        rpy="0 0 0" />
      <geometry>
        <!-- <mesh
          filename="package://humanrobo/src/meshes/R_hip_Link.STL" /> -->
          <box size="0.01 0.01 0.01"/>
      </geometry>
    </collision>
  </link>
  <joint
    name="R_hip_IO"
    type="continuous">
     <dynamics damping="0.002"/>


    <origin
      xyz="-0.044501 -0.019598 0.004238"
      rpy="0 0 0" />
    <parent
      link="waist_Link" />
    <child
      link="R_hip_Link" />
    <axis
      xyz="0 0 1" />
  </joint>
  <link
    name="R_thign_Link">
    <inertial>
      <origin
        xyz="-0.0036238 0.0086255 -0.010904"
        rpy="0 0 0" />
      <mass
        value="0.0062294" />
      <inertia
        ixx="2.4081E-06"
        ixy="0"
        ixz="0"
        iyy="2.205E-06"
        iyz="0"
        izz="9.1712E-07" />
    </inertial>
    <visual>
      <origin
        xyz="0 0 0"
        rpy="0 0 0" />
      <geometry>
        <mesh
          filename="package://humanrobo/src/meshes/R_thign_Link.STL" />
          <!-- <box size="0.01 0.01 0.01"/> -->
      </geometry>
      <material
        name="">
        <color
          rgba="0.89804 0.91765 0.92941 1" />
      </material>
    </visual>
    <collision>
      <origin
        xyz="0 0 0"
        rpy="0 0 0" />
      <geometry>
        <!-- <mesh
          filename="package://humanrobo/src/meshes/R_thign_Link.STL" /> -->
          <box size="0.01 0.01 0.01"/>
      </geometry>
    </collision>
  </link>
  <joint
    name="R_thign_SP"
    type="continuous">
     <dynamics damping="0.002"/>


    <origin
      xyz="0.028692 -0.0263 0.009"
      rpy="1.5708 -1.5708 1.5708" />
    <parent
      link="R_hip_Link" />
    <child
      link="R_thign_Link" />
    <axis
      xyz="0 1 0" />
  </joint>
  <link
    name="R_thignD_Link">
    <inertial>
      <origin
        xyz="-0.009327 -0.026501 -2.1473E-08"
        rpy="0 0 0" />
      <mass
        value="0.075004" />
      <inertia
        ixx="3.977E-05"
        ixy="0"
        ixz="0"
        iyy="1.39E-05"
        iyz="0"
        izz="4.122E-05" />
    </inertial>
    <visual>
      <origin
        xyz="0 0 0"
        rpy="0 0 0" />
      <geometry>
        <mesh
          filename="package://humanrobo/src/meshes/R_thignD_Link.STL" />
          <!-- <box size="0.01 0.01 0.01"/> -->
      </geometry>
      <material
        name="">
        <color
          rgba="0.75294 0.75294 0.75294 1" />
      </material>
    </visual>
    <collision>
      <origin
        xyz="0 0 0"
        rpy="0 0 0" />
      <geometry>
        <!-- <mesh
          filename="package://humanrobo/src/meshes/R_thignD_Link.STL" /> -->
          <box size="0.01 0.01 0.01"/>
      </geometry>
    </collision>
  </link>
  <joint
    name="R_thign_BF"
    type="continuous">
     <dynamics damping="0.002"/>


    <origin
      xyz="-0.0078324 0.022002 0"
      rpy="-1.5708 -1.5708 -1.5708" />
    <parent
      link="R_thign_Link" />
    <child
      link="R_thignD_Link" />
    <axis
      xyz="1 0 0" />
  </joint>
  <link
    name="R_shank_Link">
    <inertial>
      <origin
        xyz="-0.0097137 -0.034273 0.00041479"
        rpy="0 0 0" />
      <mass
        value="0.057967" />
      <inertia
        ixx="2.363E-05"
        ixy="0"
        ixz="0"
        iyy="1.508E-05"
        iyz="0"
        izz="2.87E-05" />
    </inertial>
    <visual>
      <origin
        xyz="0 0 0"
        rpy="0 0 0" />
      <geometry>
        <mesh
          filename="package://humanrobo/src/meshes/R_shank_Link.STL" />
          <!-- <box size="0.01 0.01 0.01"/> -->
      </geometry>
      <material
        name="">
        <color
          rgba="0.75294 0.75294 0.75294 1" />
      </material>
    </visual>
    <collision>
      <origin
        xyz="0 0 0"
        rpy="0 0 0" />
      <geometry>
        <!-- <mesh
          filename="package://humanrobo/src/meshes/R_shank_Link.STL" /> -->
          <box size="0.01 0.01 0.01"/>
      </geometry>
    </collision>
  </link>
  <joint
    name="R_knee"
    type="continuous">
     <dynamics damping="0.002"/>


    <origin
      xyz="0 -0.053002 0"
      rpy="0 0 0" />
    <parent
      link="R_thignD_Link" />
    <child
      link="R_shank_Link" />
    <axis
      xyz="1 0 0" />
  </joint>
  <link
    name="R_ankle_Link">
    <inertial>
      <origin
        xyz="-0.00013247 -0.0089377 0.0099976"
        rpy="0 0 0" />
      <mass
        value="0.0265" />
      <inertia
        ixx="1.0413E-05"
        ixy="0"
        ixz="0"
        iyy="1.5837E-05"
        iyz="0"
        izz="1.1392E-05" />
    </inertial>
    <visual>
      <origin
        xyz="0 0 0"
        rpy="0 0 0" />
      <geometry>
        <mesh
          filename="package://humanrobo/src/meshes/R_ankle_Link.STL" />
          <!-- <box size="0.01 0.01 0.01"/> -->
      </geometry>
      <material
        name="">
        <color
          rgba="0.89804 0.91765 0.92941 1" />
      </material>
    </visual>
    <collision>
      <origin
        xyz="0 0 0"
        rpy="0 0 0" />
      <geometry>
        <!-- <mesh
          filename="package://humanrobo/src/meshes/R_ankle_Link.STL" /> -->
          <box size="0.01 0.01 0.01"/>
      </geometry>
    </collision>
  </link>
  <joint
    name="R_ankle_BF"
    type="continuous">
     <dynamics damping="0.002"/>


    <origin
      xyz="0 -0.05329 0"
      rpy="-1.5708 -1.5708 1.5708" />
    <parent
      link="R_shank_Link" />
    <child
      link="R_ankle_Link" />
    <axis
      xyz="0 0 1" />
  </joint>
  <link
    name="R_foot_Link">
    <inertial>
      <origin
        xyz="-0.0075693 -0.0054605 0.005437"
        rpy="0 0 0" />
      <mass
        value="0.055122" />
      <inertia
        ixx="1.955E-05"
        ixy="0"
        ixz="0"
        iyy="2.29E-05"
        iyz="0"
        izz="1.322E-05" />
    </inertial>
    <visual>
      <origin
        xyz="-0.0085 -0.0112 0.005"
        rpy="0 0 0" />
      <geometry>
        <!-- <mesh
          filename="package://humanrobo/src/meshes/R_foot_Link.STL" /> -->
          <box size="0.041 0.011 0.055"/>
      </geometry>
      <material
        name="">
        <color
          rgba="0.75294 0.75294 0.75294 1" />
      </material>
    </visual>
    <collision>
      <origin
        xyz="-0.0085 -0.0112 0.005"
        rpy="0 0 0" />
      <geometry>
        <!-- <mesh
          filename="package://humanrobo/src/meshes/R_foot_Link.STL" /> -->
          <box size="0.041 0.011 0.055"/>
      </geometry>
    </collision>
  </link>
  <joint
    name="R_foot"
    type="continuous">
    <dynamics damping="0.002"/>


    <origin
      xyz="0 -0.027997 0.002143"
      rpy="0 1.5708 0" />
    <parent
      link="R_ankle_Link" />
    <child
      link="R_foot_Link" />
    <axis
      xyz="0 0 1" />
  </joint>


   <gazebo reference="L_foot_Link">
    <mu1>0.6</mu1>
    <mu2>0.6</mu2>
    <kp value="100000.0"/>
    <kd value="100.0"/>
  </gazebo>
  <gazebo reference="R_foot_Link">
    <mu1>0.6</mu1>
    <mu2>0.6</mu2>
    <kp value="100000.0"/>
    <kd value="100.0"/>
  </gazebo>

<!-- <transmission name="neck_yaw">
   <type>transmission_interface/SimpleTransmission</type>
   <joint name="neck_yaw">
      <hardwareInterface>hardware_interface/PositionJointInterface</hardwareInterface>
   </joint>
   <actuator name="neck_yaw">
     <hardwareInterface>hardware_interface/PositionJointInterface</hardwareInterface>
   <mechanicalReduction>1</mechanicalReduction>
   </actuator>
</transmission>
<transmission name="neck_roll">
   <type>transmission_interface/SimpleTransmission</type>
   <joint name="neck_roll">
      <hardwareInterface>hardware_interface/PositionJointInterface</hardwareInterface>
   </joint>
   <actuator name="neck_roll">
     <hardwareInterface>hardware_interface/PositionJointInterface</hardwareInterface>
   <mechanicalReduction>1</mechanicalReduction>
   </actuator>
</transmission>
<transmission name="neck_pitch">
   <type>transmission_interface/SimpleTransmission</type>
   <joint name="neck_pitch">
      <hardwareInterface>hardware_interface/PositionJointInterface</hardwareInterface>
   </joint>
   <actuator name="neck_pitch">
     <hardwareInterface>hardware_interface/PositionJointInterface</hardwareInterface>
   <mechanicalReduction>1</mechanicalReduction>
   </actuator>
</transmission>
<transmission name="L_shoulder_BF">
   <type>transmission_interface/SimpleTransmission</type>
   <joint name="L_shoulder_BF">
      <hardwareInterface>hardware_interface/PositionJointInterface</hardwareInterface>
   </joint>
   <actuator name="L_shoulder_BF">
     <hardwareInterface>hardware_interface/PositionJointInterface</hardwareInterface>
   <mechanicalReduction>1</mechanicalReduction>
   </actuator>
</transmission>
<transmission name="L_shoulder_IO">
   <type>transmission_interface/SimpleTransmission</type>
   <joint name="L_shoulder_IO">
      <hardwareInterface>hardware_interface/PositionJointInterface</hardwareInterface>
   </joint>
   <actuator name="L_shoulder_IO">
     <hardwareInterface>hardware_interface/PositionJointInterface</hardwareInterface>
   <mechanicalReduction>1</mechanicalReduction>
   </actuator>
</transmission>
<transmission name="L_elbow_SP">
   <type>transmission_interface/SimpleTransmission</type>
   <joint name="L_elbow_SP">
      <hardwareInterface>hardware_interface/PositionJointInterface</hardwareInterface>
   </joint>
   <actuator name="L_elbow_SP">
     <hardwareInterface>hardware_interface/PositionJointInterface</hardwareInterface>
   <mechanicalReduction>1</mechanicalReduction>
   </actuator>
</transmission>
<transmission name="L_elbow_BD">
   <type>transmission_interface/SimpleTransmission</type>
   <joint name="L_elbow_BD">
      <hardwareInterface>hardware_interface/PositionJointInterface</hardwareInterface>
   </joint>
   <actuator name="L_elbow_BD">
     <hardwareInterface>hardware_interface/PositionJointInterface</hardwareInterface>
   <mechanicalReduction>1</mechanicalReduction>
   </actuator>
</transmission>
<transmission name="L_hand">
   <type>transmission_interface/SimpleTransmission</type>
   <joint name="L_hand">
      <hardwareInterface>hardware_interface/PositionJointInterface</hardwareInterface>
   </joint>
   <actuator name="L_hand">
     <hardwareInterface>hardware_interface/PositionJointInterface</hardwareInterface>
   <mechanicalReduction>1</mechanicalReduction>
   </actuator>
</transmission>
<transmission name="R_shoulder_BF">
   <type>transmission_interface/SimpleTransmission</type>
   <joint name="R_shoulder_BF">
      <hardwareInterface>hardware_interface/PositionJointInterface</hardwareInterface>
   </joint>
   <actuator name="R_shoulder_BF">
     <hardwareInterface>hardware_interface/PositionJointInterface</hardwareInterface>
   <mechanicalReduction>1</mechanicalReduction>
   </actuator>
</transmission>
<transmission name="R_shoulder_IO">
   <type>transmission_interface/SimpleTransmission</type>
   <joint name="R_shoulder_IO">
      <hardwareInterface>hardware_interface/PositionJointInterface</hardwareInterface>
   </joint>
   <actuator name="R_shoulder_IO">
     <hardwareInterface>hardware_interface/PositionJointInterface</hardwareInterface>
   <mechanicalReduction>1</mechanicalReduction>
   </actuator>
</transmission> -->
<!-- <transmission name="R_elbow_SP">
   <type>transmission_interface/SimpleTransmission</type>
   <joint name="R_elbow_SP">
      <hardwareInterface>hardware_interface/PositionJointInterface</hardwareInterface>
   </joint>
   <actuator name="R_elbow_SP">
     <hardwareInterface>hardware_interface/PositionJointInterface</hardwareInterface>
   <mechanicalReduction>1</mechanicalReduction>
   </actuator>
</transmission> -->
<!-- <transmission name="R_elbow_BD">
   <type>transmission_interface/SimpleTransmission</type>
   <joint name="R_elbow_BD">
      <hardwareInterface>hardware_interface/PositionJointInterface</hardwareInterface>
   </joint>
   <actuator name="R_elbow_BD">
     <hardwareInterface>hardware_interface/PositionJointInterface</hardwareInterface>
   <mechanicalReduction>1</mechanicalReduction>
   </actuator>
</transmission>
<transmission name="R_hand">
   <type>transmission_interface/SimpleTransmission</type>
   <joint name="R_hand">
      <hardwareInterface>hardware_interface/PositionJointInterface</hardwareInterface>
   </joint>
   <actuator name="R_hand">
     <hardwareInterface>hardware_interface/PositionJointInterface</hardwareInterface>
   <mechanicalReduction>1</mechanicalReduction>
   </actuator>
</transmission> -->
<!-- <transmission name="waist_bow">
   <type>transmission_interface/SimpleTransmission</type>
   <joint name="waist_bow">
      <hardwareInterface>hardware_interface/PositionJointInterface</hardwareInterface>
   </joint>
   <actuator name="waist_bow">
     <hardwareInterface>hardware_interface/PositionJointInterface</hardwareInterface>
   <mechanicalReduction>1</mechanicalReduction>
   </actuator>
</transmission> -->
<!-- <transmission name="waist_SP">
   <type>transmission_interface/SimpleTransmission</type>
   <joint name="waist_SP">
      <hardwareInterface>hardware_interface/PositionJointInterface</hardwareInterface>
   </joint>
   <actuator name="waist_SP">
     <hardwareInterface>hardware_interface/PositionJointInterface</hardwareInterface>
   <mechanicalReduction>1</mechanicalReduction>
   </actuator>
</transmission>  -->
<transmission name="L_hip_IO">
   <type>transmission_interface/SimpleTransmission</type>
   <joint name="L_hip_IO">
      <hardwareInterface>hardware_interface/PositionJointInterface</hardwareInterface>
   </joint>
   <actuator name="L_hip_IO">
     <hardwareInterface>hardware_interface/PositionJointInterface</hardwareInterface>
   <mechanicalReduction>1</mechanicalReduction>
   </actuator>
</transmission>
<transmission name="L_thign_SP">
   <type>transmission_interface/SimpleTransmission</type>
   <joint name="L_thign_SP">
      <hardwareInterface>hardware_interface/PositionJointInterface</hardwareInterface>
   </joint>
   <actuator name="L_thign_SP">
     <hardwareInterface>hardware_interface/PositionJointInterface</hardwareInterface>
   <mechanicalReduction>1</mechanicalReduction>
   </actuator>
</transmission>
<transmission name="L_thign_BF">
   <type>transmission_interface/SimpleTransmission</type>
   <joint name="L_thign_BF">
      <hardwareInterface>hardware_interface/PositionJointInterface</hardwareInterface>
   </joint>
   <actuator name="L_thign_BF">
     <hardwareInterface>hardware_interface/PositionJointInterface</hardwareInterface>
   <mechanicalReduction>1</mechanicalReduction>
   </actuator>
</transmission>
<transmission name="L_knee">
   <type>transmission_interface/SimpleTransmission</type>
   <joint name="L_knee">
      <hardwareInterface>hardware_interface/PositionJointInterface</hardwareInterface>
   </joint>
   <actuator name="L_knee">
     <hardwareInterface>hardware_interface/PositionJointInterface</hardwareInterface>
   <mechanicalReduction>1</mechanicalReduction>
   </actuator>
</transmission>
<transmission name="L_ankle_BF">
   <type>transmission_interface/SimpleTransmission</type>
   <joint name="L_ankle_BF">
      <hardwareInterface>hardware_interface/PositionJointInterface</hardwareInterface>
   </joint>
   <actuator name="L_ankle_BF">
     <hardwareInterface>hardware_interface/PositionJointInterface</hardwareInterface>
   <mechanicalReduction>1</mechanicalReduction>
   </actuator>
</transmission>
<transmission name="L_foot">
   <type>transmission_interface/SimpleTransmission</type>
   <joint name="L_foot">
      <hardwareInterface>hardware_interface/PositionJointInterface</hardwareInterface>
   </joint>
   <actuator name="L_foot">
     <hardwareInterface>hardware_interface/PositionJointInterface</hardwareInterface>
   <mechanicalReduction>1</mechanicalReduction>
   </actuator>
</transmission>
<transmission name="R_hip_IO">
   <type>transmission_interface/SimpleTransmission</type>
   <joint name="R_hip_IO">
      <hardwareInterface>hardware_interface/PositionJointInterface</hardwareInterface>
   </joint>
   <actuator name="R_hip_IO">
     <hardwareInterface>hardware_interface/PositionJointInterface</hardwareInterface>
   <mechanicalReduction>1</mechanicalReduction>
   </actuator>
</transmission>
<transmission name="R_thign_SP">
   <type>transmission_interface/SimpleTransmission</type>
   <joint name="R_thign_SP">
      <hardwareInterface>hardware_interface/PositionJointInterface</hardwareInterface>
   </joint>
   <actuator name="R_thign_SP">
     <hardwareInterface>hardware_interface/PositionJointInterface</hardwareInterface>
   <mechanicalReduction>1</mechanicalReduction>
   </actuator>
</transmission>
<transmission name="R_thign_BF">
   <type>transmission_interface/SimpleTransmission</type>
   <joint name="R_thign_BF">
      <hardwareInterface>hardware_interface/PositionJointInterface</hardwareInterface>
   </joint>
   <actuator name="R_thign_BF">
     <hardwareInterface>hardware_interface/PositionJointInterface</hardwareInterface>
   <mechanicalReduction>1</mechanicalReduction>
   </actuator>
</transmission>
<transmission name="R_knee">
   <type>transmission_interface/SimpleTransmission</type>
   <joint name="R_knee">
      <hardwareInterface>hardware_interface/PositionJointInterface</hardwareInterface>
   </joint>
   <actuator name="R_knee">
     <hardwareInterface>hardware_interface/PositionJointInterface</hardwareInterface>
   <mechanicalReduction>1</mechanicalReduction>
   </actuator>
</transmission>
<transmission name="R_ankle_BF">
   <type>transmission_interface/SimpleTransmission</type>
   <joint name="R_ankle_BF">
      <hardwareInterface>hardware_interface/PositionJointInterface</hardwareInterface>
   </joint>
   <actuator name="R_ankle_BF">
     <hardwareInterface>hardware_interface/PositionJointInterface</hardwareInterface>
   <mechanicalReduction>1</mechanicalReduction>
   </actuator>
</transmission>
<transmission name="R_foot">
   <type>transmission_interface/SimpleTransmission</type>
   <joint name="R_foot">
      <hardwareInterface>hardware_interface/PositionJointInterface</hardwareInterface>
   </joint>
   <actuator name="R_foot">
     <hardwareInterface>hardware_interface/PositionJointInterface</hardwareInterface>
   <mechanicalReduction>1</mechanicalReduction>
   </actuator>
</transmission> 



<gazebo>
	<plugin filename="libgazebo_ros_control.so" name="gazebo_ros_control">
		<robotNamespace>humanrobo</robotNamespace>
     <controlPeriod>0.001</controlPeriod>
	</plugin>
</gazebo>
</robot>
